Workbook

Sheet 説明
A1: 投稿文 | B1: どんなポケモン使ってきそうか求む
A2: 投稿画像 | B2: ブラウンのワンピを着たドロの自撮り
A4: 投稿後しばらくして自己レスし、それをピン留め | B4: みんな本当にありがとう ここで実際に使っているポケモンを発表！！ 本編 ミミロップ、チルタリス、マホイップ、タブンネなど ポケポケ プクリンモスノウの眠りデッキ ユナイト ニンフィア、キュワワー、ピクシー

Sheet 全コメントデータ
A1: 番号 | B1: 発言者 | C1: 内容 | D1: 自己レスの前か後か | E1: 別の言及 | F1: マスタに登録忘れてない？ | G1: 一人で複数あげている
A2: 1 | B2: シゲ | C2: ランクルス | D2: 自己レスの前 | F2: =IF(ISNA(VLOOKUP(テーブル1[[#This Row],[内容]],ポケモンマスタ!A:A,1,FALSE)),"error","ok") -> ok
A3: 2 | B3: ひいらぎ | C3: シャンデラ | D3: 自己レスの前 | F3: =IF(ISNA(VLOOKUP(テーブル1[[#This Row],[内容]],ポケモンマスタ!A:A,1,FALSE)),"error","ok") -> ok | G3: ひいらぎ
A4: 3 | B4: ひいらぎ | C4: ルカリオ | D4: 自己レスの前 | F4: =IF(ISNA(VLOOKUP(テーブル1[[#This Row],[内容]],ポケモンマスタ!A:A,1,FALSE)),"error","ok") -> ok | G4: ひいらぎ
A5: 4 | B5: ひいらぎ | C5: ミミッキュ | D5: 自己レスの前 | F5: =IF(ISNA(VLOOKUP(テーブル1[[#This Row],[内容]],ポケモンマスタ!A:A,1,FALSE)),"error","ok") -> ok | G5: ひいらぎ
A6: 5 | B6: ひいらぎ | C6: ボーマンダ | D6: 自己レスの前 | F6: =IF(ISNA(VLOOKUP(テーブル1[[#This Row],[内容]],ポケモンマスタ!A:A,1,FALSE)),"error","ok") -> ok | G6: ひいらぎ
A7: 6 | B7: ひいらぎ | C7: ゲッコウガ | D7: 自己レスの前 | F7: =IF(ISNA(VLOOKUP(テーブル1[[#This Row],[内容]],ポケモンマスタ!A:A,1,FALSE)),"error","ok") -> ok | G7: ひいらぎ
A8: 7 | B8: ひいらぎ | C8: リザードン | D8: 自己レスの前 | F8: =IF(ISNA(VLOOKUP(テーブル1[[#This Row],[内容]],ポケモンマスタ!A:A,1,FALSE)),"error","ok") -> ok | G8: ひいらぎ
A9: 8 | B9: caos | C9: グラードン | D9: 自己レスの前 | F9: =IF(ISNA(VLOOKUP(テーブル1[[#This Row],[内容]],ポケモンマスタ!A:A,1,FALSE)),"error","ok") -> ok
A10: 9 | B10: ミッキー | C10: スターミー | D10: 自己レスの前 | F10: =IF(ISNA(VLOOKUP(テーブル1[[#This Row],[内容]],ポケモンマスタ!A:A,1,FALSE)),"error","ok") -> ok
A11: 10 | B11: えー。 | C11: トゲピー | D11: 自己レスの前 | F11: =IF(ISNA(VLOOKUP(テーブル1[[#This Row],[内容]],ポケモンマスタ!A:A,1,FALSE)),"error","ok") -> ok
A12: 11 | B12: ゆけお | C12: ラッキー | D12: 自己レスの前 | F12: =IF(ISNA(VLOOKUP(テーブル1[[#This Row],[内容]],ポケモンマスタ!A:A,1,FALSE)),"error","ok") -> ok | G12: ゆけお
A13: 12 | B13: ゆけお | C13: ポリゴン | D13: 自己レスの前 | F13: =IF(ISNA(VLOOKUP(テーブル1[[#This Row],[内容]],ポケモンマスタ!A:A,1,FALSE)),"error","ok") -> ok | G13: ゆけお
A14: 13 | B14: nobu | C14: バンギラス | D14: 自己レスの前 | F14: =IF(ISNA(VLOOKUP(テーブル1[[#This Row],[内容]],ポケモンマスタ!A:A,1,FALSE)),"error","ok") -> ok
A15: 14 | B15: ゆーしん | C15: コダック | D15: 自己レスの前 | F15: =IF(ISNA(VLOOKUP(テーブル1[[#This Row],[内容]],ポケモンマスタ!A:A,1,FALSE)),"error","ok") -> ok
A16: 15 | B16: りゅう | C16: ゴローニャ | D16: 自己レスの前 | F16: =IF(ISNA(VLOOKUP(テーブル1[[#This Row],[内容]],ポケモンマスタ!A:A,1,FALSE)),"error","ok") -> ok
A17: 16 | B17: 不死鳥の焼く藻 | C17: ゲンガー | D17: 自己レスの前 | F17: =IF(ISNA(VLOOKUP(テーブル1[[#This Row],[内容]],ポケモンマスタ!A:A,1,FALSE)),"error","ok") -> ok
A18: 17 | B18: 水色 | C18: プラスル | D18: 自己レスの前 | F18: =IF(ISNA(VLOOKUP(テーブル1[[#This Row],[内容]],ポケモンマスタ!A:A,1,FALSE)),"error","ok") -> ok | G18: 水色
A19: 18 | B19: 水色 | C19: マイナン | D19: 自己レスの前 | F19: =IF(ISNA(VLOOKUP(テーブル1[[#This Row],[内容]],ポケモンマスタ!A:A,1,FALSE)),"error","ok") -> ok | G19: 水色
A20: 19 | B20: わかめくん | C20: プクリン | D20: 自己レスの前 | E20: プクリンみたいな顔してる | F20: =IF(ISNA(VLOOKUP(テーブル1[[#This Row],[内容]],ポケモンマスタ!A:A,1,FALSE)),"error","ok") -> ok
A21: 20 | B21: らぺ | C21: キチキギス | D21: 自己レスの前 | F21: =IF(ISNA(VLOOKUP(テーブル1[[#This Row],[内容]],ポケモンマスタ!A:A,1,FALSE)),"error","ok") -> ok
A22: 21 | B22: 中性くん | C22: オクタン | D22: 自己レスの前 | E22: この3匹から選ぶのじゃ<3 | F22: =IF(ISNA(VLOOKUP(テーブル1[[#This Row],[内容]],ポケモンマスタ!A:A,1,FALSE)),"error","ok") -> ok | G22: 中性くん
A23: 22 | B23: 中性くん | C23: オトスパス | D23: 自己レスの前 | E23: この3匹から選ぶのじゃ<3 | F23: =IF(ISNA(VLOOKUP(テーブル1[[#This Row],[内容]],ポケモンマスタ!A:A,1,FALSE)),"error","ok") -> ok | G23: 中性くん
A24: 23 | B24: 中性くん | C24: ドククラゲ | D24: 自己レスの前 | E24: この3匹から選ぶのじゃ<3 | F24: =IF(ISNA(VLOOKUP(テーブル1[[#This Row],[内容]],ポケモンマスタ!A:A,1,FALSE)),"error","ok") -> ok | G24: 中性くん
A25: 24 | B25: 奏岬 | C25: エンペルト | D25: 自己レスの前 | F25: =IF(ISNA(VLOOKUP(テーブル1[[#This Row],[内容]],ポケモンマスタ!A:A,1,FALSE)),"error","ok") -> ok | G25: 奏岬
A26: 25 | B26: 奏岬 | C26: シャンデラ | D26: 自己レスの前 | F26: =IF(ISNA(VLOOKUP(テーブル1[[#This Row],[内容]],ポケモンマスタ!A:A,1,FALSE)),"error","ok") -> ok | G26: 奏岬
A27: 26 | B27: 奏岬 | C27: ブラッキー | D27: 自己レスの前 | F27: =IF(ISNA(VLOOKUP(テーブル1[[#This Row],[内容]],ポケモンマスタ!A:A,1,FALSE)),"error","ok") -> ok | G27: 奏岬
A28: 27 | B28: 奏岬 | C28: ジバコイル | D28: 自己レスの前 | F28: =IF(ISNA(VLOOKUP(テーブル1[[#This Row],[内容]],ポケモンマスタ!A:A,1,FALSE)),"error","ok") -> ok | G28: 奏岬
A29: 28 | B29: 奏岬 | C29: カイリュー | D29: 自己レスの前 | F29: =IF(ISNA(VLOOKUP(テーブル1[[#This Row],[内容]],ポケモンマスタ!A:A,1,FALSE)),"error","ok") -> ok | G29: 奏岬
A30: 29 | B30: 奏岬 | C30: エーフィ | D30: 自己レスの前 | F30: =IF(ISNA(VLOOKUP(テーブル1[[#This Row],[内容]],ポケモンマスタ!A:A,1,FALSE)),"error","ok") -> ok | G30: 奏岬
A31: 30 | B31: くずま | C31: ルージュラ | D31: 自己レスの前 | F31: =IF(ISNA(VLOOKUP(テーブル1[[#This Row],[内容]],ポケモンマスタ!A:A,1,FALSE)),"error","ok") -> ok
A32: 31 | B32: みお | C32: ミミッキュ | D32: 自己レスの前 | F32: =IF(ISNA(VLOOKUP(テーブル1[[#This Row],[内容]],ポケモンマスタ!A:A,1,FALSE)),"error","ok") -> ok | G32: みお
A33: 32 | B33: みお | C33: ブラッキー | D33: 自己レスの前 | F33: =IF(ISNA(VLOOKUP(テーブル1[[#This Row],[内容]],ポケモンマスタ!A:A,1,FALSE)),"error","ok") -> ok | G33: みお
A34: 33 | B34: みお | C34: カイリュー | D34: 自己レスの前 | F34: =IF(ISNA(VLOOKUP(テーブル1[[#This Row],[内容]],ポケモンマスタ!A:A,1,FALSE)),"error","ok") -> ok | G34: みお
A35: 34 | B35: みお | C35: ニョロトノ | D35: 自己レスの前 | F35: =IF(ISNA(VLOOKUP(テーブル1[[#This Row],[内容]],ポケモンマスタ!A:A,1,FALSE)),"error","ok") -> ok | G35: みお
A36: 35 | B36: みお | C36: ドオー | D36: 自己レスの前 | F36: =IF(ISNA(VLOOKUP(テーブル1[[#This Row],[内容]],ポケモンマスタ!A:A,1,FALSE)),"error","ok") -> ok | G36: みお
A37: 36 | B37: みお | C37: ポリゴン2 | D37: 自己レスの前 | F37: =IF(ISNA(VLOOKUP(テーブル1[[#This Row],[内容]],ポケモンマスタ!A:A,1,FALSE)),"error","ok") -> ok | G37: みお
A38: 37 | B38: うさぎ | C38: ゲンガー | D38: 自己レスの前 | F38: =IF(ISNA(VLOOKUP(テーブル1[[#This Row],[内容]],ポケモンマスタ!A:A,1,FALSE)),"error","ok") -> ok
A39: 38 | B39: まこっち | C39: ポッポ | D39: 自己レスの前 | F39: =IF(ISNA(VLOOKUP(テーブル1[[#This Row],[内容]],ポケモンマスタ!A:A,1,FALSE)),"error","ok") -> ok
A40: 39 | B40: ゆでん | C40: マダツボミ | D40: 自己レスの前 | F40: =IF(ISNA(VLOOKUP(テーブル1[[#This Row],[内容]],ポケモンマスタ!A:A,1,FALSE)),"error","ok") -> ok | G40: ゆでん
...

Sheet ポケモン集計
A1: 個数 / 内容 | B1: 列ラベル | G1: 行ラベル | H1: 個数 / 一人で複数あげている
A2: 行ラベル | B2: 自己レスの前 | C2: 自己レスの後 | D2: 自己レス | E2: 総計 | G2: アシレーヌ
A3: アシレーヌ | C3: 1 | E3: 1 | G3: アズマオウ | H3: 1
A4: アズマオウ | C4: 1 | E4: 1 | G4: アルセウス | H4: 1
A5: アルセウス | C5: 1 | E5: 1 | G5: アローラゴローン | H5: 1
A6: アローラゴローン | C6: 1 | E6: 1 | G6: イーブイ | H6: 3
A7: イーブイ | B7: 3 | C7: 6 | E7: 9 | G7: イルカマン
A8: イルカマン | C8: 1 | E8: 1 | G8: ウソッキー
A9: ウソッキー | B9: 1 | C9: 1 | E9: 2 | G9: ウツドン | H9: 1
A10: ウツドン | B10: 1 | E10: 1 | G10: ウパー
A11: ウパー | C11: 1 | E11: 1 | G11: エーフィ | H11: 1
A12: エーフィ | B12: 1 | E12: 1 | G12: エネコ
A13: エネコ | B13: 2 | E13: 2 | G13: エルフーン | H13: 1
A14: エルフーン | C14: 1 | E14: 1 | G14: エルレイド
A15: エルレイド | C15: 1 | E15: 1 | G15: エレブー
A16: エレブー | C16: 1 | E16: 1 | G16: エンペルト | H16: 1
A17: エンペルト | B17: 1 | C17: 1 | E17: 2 | G17: オオタチ | H17: 1
A18: オオタチ | B18: 1 | E18: 1 | G18: オーロット | H18: 1
A19: オーロット | B19: 1 | E19: 1 | G19: オーロンゲ | H19: 1
A20: オーロンゲ | B20: 2 | E20: 2 | G20: オクタン | H20: 1
A21: オクタン | B21: 1 | E21: 1 | G21: オタマロ
A22: オタマロ | C22: 1 | E22: 1 | G22: オトスパス | H22: 2
A23: オトスパス | B23: 2 | E23: 2 | G23: オニゴーリ | H23: 1
A24: オニゴーリ | B24: 1 | E24: 1 | G24: カイオーガ | H24: 1
A25: カイオーガ | C25: 1 | E25: 1 | G25: カイリュー | H25: 5
A26: カイリュー | B26: 5 | C26: 1 | E26: 6 | G26: カビゴン | H26: 2
A27: カビゴン | B27: 2 | C27: 1 | E27: 3 | G27: ガブリアス
A28: ガブリアス | B28: 1 | E28: 1 | G28: カポエラー
A29: カポエラー | B29: 1 | E29: 1 | G29: ガマゲロゲ | H29: 1
A30: ガマゲロゲ | B30: 1 | E30: 1 | G30: カメックス
A31: カメックス | C31: 1 | E31: 1 | G31: カラサリス | H31: 1
A32: カラサリス | C32: 1 | E32: 1 | G32: キチキギス
A33: キチキギス | B33: 1 | E33: 1 | G33: キノガッサ
A34: キノガッサ | C34: 1 | E34: 1 | G34: キャタピー | H34: 1
A35: キャタピー | B35: 1 | C35: 1 | E35: 2 | G35: ギャラドス | H35: 1
A36: ギャラドス | B36: 2 | E36: 2 | G36: キュワワー
A37: キュワワー | D37: 1 | E37: 1 | G37: キョジオーン | H37: 1
A38: キョジオーン | B38: 1 | E38: 1 | G38: ギラティナ
A39: ギラティナ | C39: 1 | E39: 1 | G39: ギルガルド
A40: ギルガルド | C40: 1 | E40: 1 | G40: キレイハナ | H40: 1
...

Sheet ポケモンマスタ
A1: ポケモン | B1: 言われた回数 | C1: うち、自己レス前 | D1: うち、自己レス後 | E1: 一言で言えば | F1: ジェンダー | G1: タイプ１ | H1: タイプ２ | I1: 知名度 | J1: どのトレーナーの？ | K1: その意見は | L1: かわいさ | M1: かっこよさ | N1: うつくしさ | O1: 個性的 | P1: 対戦強さ | Q1: 一人で複数あげている人があげた回数
A2: ミミッキュ | B2: =COUNTIFS(全コメントデータ!C:C,テーブル2[[#This Row],[ポケモン]],全コメントデータ!D:D,"<>"&"自己レス") -> 10 | C2: =COUNTIFS(全コメントデータ!C:C,テーブル2[[#This Row],[ポケモン]],全コメントデータ!D:D,"自己レスの前") -> 5 | D2: =COUNTIFS(全コメントデータ!C:C,テーブル2[[#This Row],[ポケモン]],全コメントデータ!D:D,"自己レスの後") -> 5 | E2: かわいい | F2: 女の子向け | G2: ゴースト | H2: フェアリー | I2: 一般人にもメジャー | J2: アセロラ | K2: =IF(テーブル2[[#This Row],[言われた回数]]>2,"多数派","少数派") -> 多数派 | L2: かわいい | M2: 普通 | N2: 普通 | O2: 個性的 | P2: ガチポケ | Q2: =COUNTIFS(全コメントデータ!C:C,テーブル2[[#This Row],[ポケモン]],全コメントデータ!G:G,"<>"&"") -> 5
A3: プリン | B3: =COUNTIFS(全コメントデータ!C:C,テーブル2[[#This Row],[ポケモン]],全コメントデータ!D:D,"<>"&"自己レス") -> 8 | C3: =COUNTIFS(全コメントデータ!C:C,テーブル2[[#This Row],[ポケモン]],全コメントデータ!D:D,"自己レスの前") -> 5 | D3: =COUNTIFS(全コメントデータ!C:C,テーブル2[[#This Row],[ポケモン]],全コメントデータ!D:D,"自己レスの後") -> 3 | E3: かわいい | F3: 女の子向け | G3: ノーマル | H3: フェアリー | I3: 一般人にもメジャー | J3: ー | K3: =IF(テーブル2[[#This Row],[言われた回数]]>2,"多数派","少数派") -> 多数派 | L3: かわいい | M3: 普通 | N3: 普通 | O3: 無難 | P3: 進化前 | Q3: =COUNTIFS(全コメントデータ!C:C,テーブル2[[#This Row],[ポケモン]],全コメントデータ!G:G,"<>"&"") -> 5
A4: カイリュー | B4: =COUNTIFS(全コメントデータ!C:C,テーブル2[[#This Row],[ポケモン]],全コメントデータ!D:D,"<>"&"自己レス") -> 6 | C4: =COUNTIFS(全コメントデータ!C:C,テーブル2[[#This Row],[ポケモン]],全コメントデータ!D:D,"自己レスの前") -> 5 | D4: =COUNTIFS(全コメントデータ!C:C,テーブル2[[#This Row],[ポケモン]],全コメントデータ!D:D,"自己レスの後") -> 1 | E4: 強い | F4: 男の子向け | G4: ドラゴン | H4: ひこう | I4: 既プレイ層にはメジャー | J4: ワタル | K4: =IF(テーブル2[[#This Row],[言われた回数]]>2,"多数派","少数派") -> 多数派 | L4: ややかわいい | M4: ややかっこいい | N4: 普通 | O4: やや個性的 | P4: ガチポケ | Q4: =COUNTIFS(全コメントデータ!C:C,テーブル2[[#This Row],[ポケモン]],全コメントデータ!G:G,"<>"&"") -> 5
A5: サーナイト | B5: =COUNTIFS(全コメントデータ!C:C,テーブル2[[#This Row],[ポケモン]],全コメントデータ!D:D,"<>"&"自己レス") -> 8 | C5: =COUNTIFS(全コメントデータ!C:C,テーブル2[[#This Row],[ポケモン]],全コメントデータ!D:D,"自己レスの前") -> 3 | D5: =COUNTIFS(全コメントデータ!C:C,テーブル2[[#This Row],[ポケモン]],全コメントデータ!D:D,"自己レスの後") -> 5 | E5: かわいい | F5: 女の子向け | G5: エスパー | H5: フェアリー | J5: ミツル、カルネ | K5: =IF(テーブル2[[#This Row],[言われた回数]]>2,"多数派","少数派") -> 多数派 | Q5: =COUNTIFS(全コメントデータ!C:C,テーブル2[[#This Row],[ポケモン]],全コメントデータ!G:G,"<>"&"") -> 4
A6: ゲンガー | B6: =COUNTIFS(全コメントデータ!C:C,テーブル2[[#This Row],[ポケモン]],全コメントデータ!D:D,"<>"&"自己レス") -> 7 | C6: =COUNTIFS(全コメントデータ!C:C,テーブル2[[#This Row],[ポケモン]],全コメントデータ!D:D,"自己レスの前") -> 4 | D6: =COUNTIFS(全コメントデータ!C:C,テーブル2[[#This Row],[ポケモン]],全コメントデータ!D:D,"自己レスの後") -> 3 | E6: スプーキー | F6: 男の子向け | G6: ゴースト | H6: どく | I6: 一般人にもメジャー | J6: オニオン、キクコ、プルメリ | K6: =IF(テーブル2[[#This Row],[言われた回数]]>2,"多数派","少数派") -> 多数派 | L6: ややかわいい | M6: ややかっこいい | N6: 普通 | O6: 個性的 | P6: ガチポケ | Q6: =COUNTIFS(全コメントデータ!C:C,テーブル2[[#This Row],[ポケモン]],全コメントデータ!G:G,"<>"&"") -> 4
A7: ラッキー | B7: =COUNTIFS(全コメントデータ!C:C,テーブル2[[#This Row],[ポケモン]],全コメントデータ!D:D,"<>"&"自己レス") -> 6 | C7: =COUNTIFS(全コメントデータ!C:C,テーブル2[[#This Row],[ポケモン]],全コメントデータ!D:D,"自己レスの前") -> 3 | D7: =COUNTIFS(全コメントデータ!C:C,テーブル2[[#This Row],[ポケモン]],全コメントデータ!D:D,"自己レスの後") -> 3 | E7: かわいい | F7: 女の子向け | G7: ノーマル | H7: 0 | J7: ー | K7: =IF(テーブル2[[#This Row],[言われた回数]]>2,"多数派","少数派") -> 多数派 | Q7: =COUNTIFS(全コメントデータ!C:C,テーブル2[[#This Row],[ポケモン]],全コメントデータ!G:G,"<>"&"") -> 4
A8: ブラッキー | B8: =COUNTIFS(全コメントデータ!C:C,テーブル2[[#This Row],[ポケモン]],全コメントデータ!D:D,"<>"&"自己レス") -> 4 | C8: =COUNTIFS(全コメントデータ!C:C,テーブル2[[#This Row],[ポケモン]],全コメントデータ!D:D,"自己レスの前") -> 3 | D8: =COUNTIFS(全コメントデータ!C:C,テーブル2[[#This Row],[ポケモン]],全コメントデータ!D:D,"自己レスの後") -> 1 | E8: かっこいい | F8: 男の子向け | G8: あく | H8: 0 | J8: カリン | K8: =IF(テーブル2[[#This Row],[言われた回数]]>2,"多数派","少数派") -> 多数派 | Q8: =COUNTIFS(全コメントデータ!C:C,テーブル2[[#This Row],[ポケモン]],全コメントデータ!G:G,"<>"&"") -> 4
A9: ジラーチ | B9: =COUNTIFS(全コメントデータ!C:C,テーブル2[[#This Row],[ポケモン]],全コメントデータ!D:D,"<>"&"自己レス") -> 4 | C9: =COUNTIFS(全コメントデータ!C:C,テーブル2[[#This Row],[ポケモン]],全コメントデータ!D:D,"自己レスの前") -> 1 | D9: =COUNTIFS(全コメントデータ!C:C,テーブル2[[#This Row],[ポケモン]],全コメントデータ!D:D,"自己レスの後") -> 3 | E9: かわいい | F9: 女の子向け | G9: はがね | H9: エスパー | J9: ー | K9: =IF(テーブル2[[#This Row],[言われた回数]]>2,"多数派","少数派") -> 多数派 | Q9: =COUNTIFS(全コメントデータ!C:C,テーブル2[[#This Row],[ポケモン]],全コメントデータ!G:G,"<>"&"") -> 4
A10: イーブイ | B10: =COUNTIFS(全コメントデータ!C:C,テーブル2[[#This Row],[ポケモン]],全コメントデータ!D:D,"<>"&"自己レス") -> 9 | C10: =COUNTIFS(全コメントデータ!C:C,テーブル2[[#This Row],[ポケモン]],全コメントデータ!D:D,"自己レスの前") -> 3 | D10: =COUNTIFS(全コメントデータ!C:C,テーブル2[[#This Row],[ポケモン]],全コメントデータ!D:D,"自己レスの後") -> 6 | E10: かわいい | F10: 女の子向け | G10: ノーマル | H10: 0 | I10: 一般人にもメジャー | J10: グリーン、アユミ | K10: =IF(テーブル2[[#This Row],[言われた回数]]>2,"多数派","少数派") -> 多数派 | L10: とてもかわいい | M10: 普通 | N10: 普通 | O10: 無難 | P10: 進化前 | Q10: =COUNTIFS(全コメントデータ!C:C,テーブル2[[#This Row],[ポケモン]],全コメントデータ!G:G,"<>"&"") -> 3
A11: ピクシー | B11: =COUNTIFS(全コメントデータ!C:C,テーブル2[[#This Row],[ポケモン]],全コメントデータ!D:D,"<>"&"自己レス") -> 5 | C11: =COUNTIFS(全コメントデータ!C:C,テーブル2[[#This Row],[ポケモン]],全コメントデータ!D:D,"自己レスの前") -> 2 | D11: =COUNTIFS(全コメントデータ!C:C,テーブル2[[#This Row],[ポケモン]],全コメントデータ!D:D,"自己レスの後") -> 3 | E11: かわいい | F11: 女の子向け | G11: フェアリー | H11: 0 | I11: 既プレイ層にはメジャー | J11: ー | K11: =IF(テーブル2[[#This Row],[言われた回数]]>2,"多数派","少数派") -> 多数派 | L11: かわいい | M11: 普通 | N11: 普通 | O11: 無難 | P11: 弱い | Q11: =COUNTIFS(全コメントデータ!C:C,テーブル2[[#This Row],[ポケモン]],全コメントデータ!G:G,"<>"&"") -> 3
A12: トゲピー | B12: =COUNTIFS(全コメントデータ!C:C,テーブル2[[#This Row],[ポケモン]],全コメントデータ!D:D,"<>"&"自己レス") -> 5 | C12: =COUNTIFS(全コメントデータ!C:C,テーブル2[[#This Row],[ポケモン]],全コメントデータ!D:D,"自己レスの前") -> 5 | D12: =COUNTIFS(全コメントデータ!C:C,テーブル2[[#This Row],[ポケモン]],全コメントデータ!D:D,"自己レスの後") -> 0 | E12: かわいい | F12: 女の子向け | G12: フェアリー | H12: 0 | I12: 既プレイ層にはメジャー | J12: カスミ、ウォロ | K12: =IF(テーブル2[[#This Row],[言われた回数]]>2,"多数派","少数派") -> 多数派 | L12: かわいい | M12: 普通 | N12: 普通 | O12: 無難 | P12: 進化前 | Q12: =COUNTIFS(全コメントデータ!C:C,テーブル2[[#This Row],[ポケモン]],全コメントデータ!G:G,"<>"&"") -> 3
A13: ミミロップ | B13: =COUNTIFS(全コメントデータ!C:C,テーブル2[[#This Row],[ポケモン]],全コメントデータ!D:D,"<>"&"自己レス") -> 4 | C13: =COUNTIFS(全コメントデータ!C:C,テーブル2[[#This Row],[ポケモン]],全コメントデータ!D:D,"自己レスの前") -> 2 | D13: =COUNTIFS(全コメントデータ!C:C,テーブル2[[#This Row],[ポケモン]],全コメントデータ!D:D,"自己レスの後") -> 2 | E13: かわいい | F13: 女の子向け | G13: ノーマル | H13: 0 | J13: ー | K13: =IF(テーブル2[[#This Row],[言われた回数]]>2,"多数派","少数派") -> 多数派 | Q13: =COUNTIFS(全コメントデータ!C:C,テーブル2[[#This Row],[ポケモン]],全コメントデータ!G:G,"<>"&"") -> 3
A14: ハピナス | B14: =COUNTIFS(全コメントデータ!C:C,テーブル2[[#This Row],[ポケモン]],全コメントデータ!D:D,"<>"&"自己レス") -> 4 | C14: =COUNTIFS(全コメントデータ!C:C,テーブル2[[#This Row],[ポケモン]],全コメントデータ!D:D,"自己レスの前") -> 1 | D14: =COUNTIFS(全コメントデータ!C:C,テーブル2[[#This Row],[ポケモン]],全コメントデータ!D:D,"自己レスの後") -> 3 | E14: かわいい | F14: 女の子向け | G14: ノーマル | H14: 0 | J14: モミ | K14: =IF(テーブル2[[#This Row],[言われた回数]]>2,"多数派","少数派") -> 多数派 | Q14: =COUNTIFS(全コメントデータ!C:C,テーブル2[[#This Row],[ポケモン]],全コメントデータ!G:G,"<>"&"") -> 3
A15: シャンデラ | B15: =COUNTIFS(全コメントデータ!C:C,テーブル2[[#This Row],[ポケモン]],全コメントデータ!D:D,"<>"&"自己レス") -> 3 | C15: =COUNTIFS(全コメントデータ!C:C,テーブル2[[#This Row],[ポケモン]],全コメントデータ!D:D,"自己レスの前") -> 2 | D15: =COUNTIFS(全コメントデータ!C:C,テーブル2[[#This Row],[ポケモン]],全コメントデータ!D:D,"自己レスの後") -> 1 | E15: かわいい | F15: 女の子向け | G15: ゴースト | H15: ほのお | I15: 既プレイ層にはメジャー | J15: ノボリ、シキミ | K15: =IF(テーブル2[[#This Row],[言われた回数]]>2,"多数派","少数派") -> 多数派 | L15: かわいい | M15: 普通 | N15: きれい | P15: 普通 | Q15: =COUNTIFS(全コメントデータ!C:C,テーブル2[[#This Row],[ポケモン]],全コメントデータ!G:G,"<>"&"") -> 3
A16: プクリン | B16: =COUNTIFS(全コメントデータ!C:C,テーブル2[[#This Row],[ポケモン]],全コメントデータ!D:D,"<>"&"自己レス") -> 6 | C16: =COUNTIFS(全コメントデータ!C:C,テーブル2[[#This Row],[ポケモン]],全コメントデータ!D:D,"自己レスの前") -> 3 | D16: =COUNTIFS(全コメントデータ!C:C,テーブル2[[#This Row],[ポケモン]],全コメントデータ!D:D,"自己レスの後") -> 3 | E16: かわいい | F16: 女の子向け | G16: ノーマル | H16: フェアリー | I16: 既プレイ層にはメジャー | J16: ー | K16: =IF(テーブル2[[#This Row],[言われた回数]]>2,"多数派","少数派") -> 多数派 | L16: かわいい | M16: 普通 | N16: 普通 | O16: 無難 | P16: 弱い | Q16: =COUNTIFS(全コメントデータ!C:C,テーブル2[[#This Row],[ポケモン]],全コメントデータ!G:G,"<>"&"") -> 2
A17: ピッピ | B17: =COUNTIFS(全コメントデータ!C:C,テーブル2[[#This Row],[ポケモン]],全コメントデータ!D:D,"<>"&"自己レス") -> 6 | C17: =COUNTIFS(全コメントデータ!C:C,テーブル2[[#This Row],[ポケモン]],全コメントデータ!D:D,"自己レスの前") -> 3 | D17: =COUNTIFS(全コメントデータ!C:C,テーブル2[[#This Row],[ポケモン]],全コメントデータ!D:D,"自己レスの後") -> 3 | E17: かわいい | F17: 女の子向け | G17: フェアリー | H17: 0 | J17: リーリエ | K17: =IF(テーブル2[[#This Row],[言われた回数]]>2,"多数派","少数派") -> 多数派 | Q17: =COUNTIFS(全コメントデータ!C:C,テーブル2[[#This Row],[ポケモン]],全コメントデータ!G:G,"<>"&"") -> 2
A18: ニンフィア | B18: =COUNTIFS(全コメントデータ!C:C,テーブル2[[#This Row],[ポケモン]],全コメントデータ!D:D,"<>"&"自己レス") -> 3 | C18: =COUNTIFS(全コメントデータ!C:C,テーブル2[[#This Row],[ポケモン]],全コメントデータ!D:D,"自己レスの前") -> 1 | D18: =COUNTIFS(全コメントデータ!C:C,テーブル2[[#This Row],[ポケモン]],全コメントデータ!D:D,"自己レスの後") -> 2 | E18: かわいい | F18: 女の子向け | G18: フェアリー | H18: 0 | J18: ボタン | K18: =IF(テーブル2[[#This Row],[言われた回数]]>2,"多数派","少数派") -> 多数派 | Q18: =COUNTIFS(全コメントデータ!C:C,テーブル2[[#This Row],[ポケモン]],全コメントデータ!G:G,"<>"&"") -> 2
A19: ナゾノクサ | B19: =COUNTIFS(全コメントデータ!C:C,テーブル2[[#This Row],[ポケモン]],全コメントデータ!D:D,"<>"&"自己レス") -> 3 | C19: =COUNTIFS(全コメントデータ!C:C,テーブル2[[#This Row],[ポケモン]],全コメントデータ!D:D,"自己レスの前") -> 2 | D19: =COUNTIFS(全コメントデータ!C:C,テーブル2[[#This Row],[ポケモン]],全コメントデータ!D:D,"自己レスの後") -> 1 | E19: モンスター | F19: 女の子向け | G19: くさ | H19: どく | K19: =IF(テーブル2[[#This Row],[言われた回数]]>2,"多数派","少数派") -> 多数派 | Q19: =COUNTIFS(全コメントデータ!C:C,テーブル2[[#This Row],[ポケモン]],全コメントデータ!G:G,"<>"&"") -> 2
A20: カビゴン | B20: =COUNTIFS(全コメントデータ!C:C,テーブル2[[#This Row],[ポケモン]],全コメントデータ!D:D,"<>"&"自己レス") -> 3 | C20: =COUNTIFS(全コメントデータ!C:C,テーブル2[[#This Row],[ポケモン]],全コメントデータ!D:D,"自己レスの前") -> 2 | D20: =COUNTIFS(全コメントデータ!C:C,テーブル2[[#This Row],[ポケモン]],全コメントデータ!D:D,"自己レスの後") -> 1 | E20: コミカル | F20: 男の子向け | G20: ノーマル | H20: 0 | J20: レッド | K20: =IF(テーブル2[[#This Row],[言われた回数]]>2,"多数派","少数派") -> 多数派 | Q20: =COUNTIFS(全コメントデータ!C:C,テーブル2[[#This Row],[ポケモン]],全コメントデータ!G:G,"<>"&"") -> 2
A21: ボーマンダ | B21: =COUNTIFS(全コメントデータ!C:C,テーブル2[[#This Row],[ポケモン]],全コメントデータ!D:D,"<>"&"自己レス") -> 3 | C21: =COUNTIFS(全コメントデータ!C:C,テーブル2[[#This Row],[ポケモン]],全コメントデータ!D:D,"自己レスの前") -> 2 | D21: =COUNTIFS(全コメントデータ!C:C,テーブル2[[#This Row],[ポケモン]],全コメントデータ!D:D,"自己レスの後") -> 1 | E21: かっこいい | F21: 男の子向け | G21: ドラゴン | H21: ひこう | J21: ヒガナ | K21: =IF(テーブル2[[#This Row],[言われた回数]]>2,"多数派","少数派") -> 多数派 | Q21: =COUNTIFS(全コメントデータ!C:C,テーブル2[[#This Row],[ポケモン]],全コメントデータ!G:G,"<>"&"") -> 2
A22: トゲキッス | B22: =COUNTIFS(全コメントデータ!C:C,テーブル2[[#This Row],[ポケモン]],全コメントデータ!D:D,"<>"&"自己レス") -> 3 | C22: =COUNTIFS(全コメントデータ!C:C,テーブル2[[#This Row],[ポケモン]],全コメントデータ!D:D,"自己レスの前") -> 1 | D22: =COUNTIFS(全コメントデータ!C:C,テーブル2[[#This Row],[ポケモン]],全コメントデータ!D:D,"自己レスの後") -> 2 | E22: かわいい | F22: 女の子向け | G22: フェアリー | H22: ひこう | J22: シロナ | K22: =IF(テーブル2[[#This Row],[言われた回数]]>2,"多数派","少数派") -> 多数派 | Q22: =COUNTIFS(全コメントデータ!C:C,テーブル2[[#This Row],[ポケモン]],全コメントデータ!G:G,"<>"&"") -> 2
A23: オトスパス | B23: =COUNTIFS(全コメントデータ!C:C,テーブル2[[#This Row],[ポケモン]],全コメントデータ!D:D,"<>"&"自己レス") -> 2 | C23: =COUNTIFS(全コメントデータ!C:C,テーブル2[[#This Row],[ポケモン]],全コメントデータ!D:D,"自己レスの前") -> 2 | D23: =COUNTIFS(全コメントデータ!C:C,テーブル2[[#This Row],[ポケモン]],全コメントデータ!D:D,"自己レスの後") -> 0 | E23: いかつい | F23: 男の子向け | G23: かくとう | H23: 0 | K23: =IF(テーブル2[[#This Row],[言われた回数]]>2,"多数派","少数派") -> 少数派 | Q23: =COUNTIFS(全コメントデータ!C:C,テーブル2[[#This Row],[ポケモン]],全コメントデータ!G:G,"<>"&"") -> 2
A24: ドオー | B24: =COUNTIFS(全コメントデータ!C:C,テーブル2[[#This Row],[ポケモン]],全コメントデータ!D:D,"<>"&"自己レス") -> 2 | C24: =COUNTIFS(全コメントデータ!C:C,テーブル2[[#This Row],[ポケモン]],全コメントデータ!D:D,"自己レスの前") -> 2 | D24: =COUNTIFS(全コメントデータ!C:C,テーブル2[[#This Row],[ポケモン]],全コメントデータ!D:D,"自己レスの後") -> 0 | E24: かわいい | F24: 男の子向け | G24: どく | H24: じめん | K24: =IF(テーブル2[[#This Row],[言われた回数]]>2,"多数派","少数派") -> 少数派 | Q24: =COUNTIFS(全コメントデータ!C:C,テーブル2[[#This Row],[ポケモン]],全コメントデータ!G:G,"<>"&"") -> 2
A25: コノヨザル | B25: =COUNTIFS(全コメントデータ!C:C,テーブル2[[#This Row],[ポケモン]],全コメントデータ!D:D,"<>"&"自己レス") -> 2 | C25: =COUNTIFS(全コメントデータ!C:C,テーブル2[[#This Row],[ポケモン]],全コメントデータ!D:D,"自己レスの前") -> 2 | D25: =COUNTIFS(全コメントデータ!C:C,テーブル2[[#This Row],[ポケモン]],全コメントデータ!D:D,"自己レスの後") -> 0 | E25: いかつい | F25: 男の子向け | G25: かくとう | H25: ゴースト | J25: ビワ | K25: =IF(テーブル2[[#This Row],[言われた回数]]>2,"多数派","少数派") -> 少数派 | Q25: =COUNTIFS(全コメントデータ!C:C,テーブル2[[#This Row],[ポケモン]],全コメントデータ!G:G,"<>"&"") -> 2
A26: ルカリオ | B26: =COUNTIFS(全コメントデータ!C:C,テーブル2[[#This Row],[ポケモン]],全コメントデータ!D:D,"<>"&"自己レス") -> 2 | C26: =COUNTIFS(全コメントデータ!C:C,テーブル2[[#This Row],[ポケモン]],全コメントデータ!D:D,"自己レスの前") -> 1 | D26: =COUNTIFS(全コメントデータ!C:C,テーブル2[[#This Row],[ポケモン]],全コメントデータ!D:D,"自己レスの後") -> 1 | E26: かっこいい | F26: 男の子向け | G26: かくとう | H26: はがね | K26: =IF(テーブル2[[#This Row],[言われた回数]]>2,"多数派","少数派") -> 少数派 | Q26: =COUNTIFS(全コメントデータ!C:C,テーブル2[[#This Row],[ポケモン]],全コメントデータ!G:G,"<>"&"") -> 2
A27: ゴースト | B27: =COUNTIFS(全コメントデータ!C:C,テーブル2[[#This Row],[ポケモン]],全コメントデータ!D:D,"<>"&"自己レス") -> 2 | C27: =COUNTIFS(全コメントデータ!C:C,テーブル2[[#This Row],[ポケモン]],全コメントデータ!D:D,"自己レスの前") -> 1 | D27: =COUNTIFS(全コメントデータ!C:C,テーブル2[[#This Row],[ポケモン]],全コメントデータ!D:D,"自己レスの後") -> 1 | E27: モンスター | F27: 男の子向け | G27: ゴースト | H27: どく | K27: =IF(テーブル2[[#This Row],[言われた回数]]>2,"多数派","少数派") -> 少数派 | Q27: =COUNTIFS(全コメントデータ!C:C,テーブル2[[#This Row],[ポケモン]],全コメントデータ!G:G,"<>"&"") -> 2
A28: ミミロル | B28: =COUNTIFS(全コメントデータ!C:C,テーブル2[[#This Row],[ポケモン]],全コメントデータ!D:D,"<>"&"自己レス") -> 2 | C28: =COUNTIFS(全コメントデータ!C:C,テーブル2[[#This Row],[ポケモン]],全コメントデータ!D:D,"自己レスの前") -> 1 | D28: =COUNTIFS(全コメントデータ!C:C,テーブル2[[#This Row],[ポケモン]],全コメントデータ!D:D,"自己レスの後") -> 1 | E28: かわいい | F28: 女の子向け | G28: ノーマル | H28: 0 | K28: =IF(テーブル2[[#This Row],[言われた回数]]>2,"多数派","少数派") -> 少数派 | Q28: =COUNTIFS(全コメントデータ!C:C,テーブル2[[#This Row],[ポケモン]],全コメントデータ!G:G,"<>"&"") -> 2
A29: パチリス | B29: =COUNTIFS(全コメントデータ!C:C,テーブル2[[#This Row],[ポケモン]],全コメントデータ!D:D,"<>"&"自己レス") -> 4 | C29: =COUNTIFS(全コメントデータ!C:C,テーブル2[[#This Row],[ポケモン]],全コメントデータ!D:D,"自己レスの前") -> 2 | D29: =COUNTIFS(全コメントデータ!C:C,テーブル2[[#This Row],[ポケモン]],全コメントデータ!D:D,"自己レスの後") -> 2 | E29: かわいい | F29: 女の子向け | G29: でんき | H29: 0 | J29: ー | K29: =IF(テーブル2[[#This Row],[言われた回数]]>2,"多数派","少数派") -> 多数派 | Q29: =COUNTIFS(全コメントデータ!C:C,テーブル2[[#This Row],[ポケモン]],全コメントデータ!G:G,"<>"&"") -> 1
A30: コラッタ | B30: =COUNTIFS(全コメントデータ!C:C,テーブル2[[#This Row],[ポケモン]],全コメントデータ!D:D,"<>"&"自己レス") -> 4 | C30: =COUNTIFS(全コメントデータ!C:C,テーブル2[[#This Row],[ポケモン]],全コメントデータ!D:D,"自己レスの前") -> 1 | D30: =COUNTIFS(全コメントデータ!C:C,テーブル2[[#This Row],[ポケモン]],全コメントデータ!D:D,"自己レスの後") -> 3 | E30: モンスター | F30: 男の子向け | G30: ノーマル | H30: 0 | J30: ー | K30: =IF(テーブル2[[#This Row],[言われた回数]]>2,"多数派","少数派") -> 多数派 | Q30: =COUNTIFS(全コメントデータ!C:C,テーブル2[[#This Row],[ポケモン]],全コメントデータ!G:G,"<>"&"") -> 1
A31: ゴチルゼル | B31: =COUNTIFS(全コメントデータ!C:C,テーブル2[[#This Row],[ポケモン]],全コメントデータ!D:D,"<>"&"自己レス") -> 4 | C31: =COUNTIFS(全コメントデータ!C:C,テーブル2[[#This Row],[ポケモン]],全コメントデータ!D:D,"自己レスの前") -> 1 | D31: =COUNTIFS(全コメントデータ!C:C,テーブル2[[#This Row],[ポケモン]],全コメントデータ!D:D,"自己レスの後") -> 3 | E31: かわいい | F31: 女の子向け | G31: エスパー | H31: 0 | J31: ー | K31: =IF(テーブル2[[#This Row],[言われた回数]]>2,"多数派","少数派") -> 多数派 | Q31: =COUNTIFS(全コメントデータ!C:C,テーブル2[[#This Row],[ポケモン]],全コメントデータ!G:G,"<>"&"") -> 1
A32: グラードン | B32: =COUNTIFS(全コメントデータ!C:C,テーブル2[[#This Row],[ポケモン]],全コメントデータ!D:D,"<>"&"自己レス") -> 4 | C32: =COUNTIFS(全コメントデータ!C:C,テーブル2[[#This Row],[ポケモン]],全コメントデータ!D:D,"自己レスの前") -> 1 | D32: =COUNTIFS(全コメントデータ!C:C,テーブル2[[#This Row],[ポケモン]],全コメントデータ!D:D,"自己レスの後") -> 3 | E32: 強い | F32: 男の子向け | G32: じめん | H32: 0 | K32: =IF(テーブル2[[#This Row],[言われた回数]]>2,"多数派","少数派") -> 多数派 | Q32: =COUNTIFS(全コメントデータ!C:C,テーブル2[[#This Row],[ポケモン]],全コメントデータ!G:G,"<>"&"") -> 1
A33: ポリゴン2 | B33: =COUNTIFS(全コメントデータ!C:C,テーブル2[[#This Row],[ポケモン]],全コメントデータ!D:D,"<>"&"自己レス") -> 2 | C33: =COUNTIFS(全コメントデータ!C:C,テーブル2[[#This Row],[ポケモン]],全コメントデータ!D:D,"自己レスの前") -> 2 | D33: =COUNTIFS(全コメントデータ!C:C,テーブル2[[#This Row],[ポケモン]],全コメントデータ!D:D,"自己レスの後") -> 0 | E33: テクニカル | F33: 男の子向け | G33: ノーマル | H33: 0 | K33: =IF(テーブル2[[#This Row],[言われた回数]]>2,"多数派","少数派") -> 少数派 | Q33: =COUNTIFS(全コメントデータ!C:C,テーブル2[[#This Row],[ポケモン]],全コメントデータ!G:G,"<>"&"") -> 1
A34: ポッポ | B34: =COUNTIFS(全コメントデータ!C:C,テーブル2[[#This Row],[ポケモン]],全コメントデータ!D:D,"<>"&"自己レス") -> 2 | C34: =COUNTIFS(全コメントデータ!C:C,テーブル2[[#This Row],[ポケモン]],全コメントデータ!D:D,"自己レスの前") -> 2 | D34: =COUNTIFS(全コメントデータ!C:C,テーブル2[[#This Row],[ポケモン]],全コメントデータ!D:D,"自己レスの後") -> 0 | E34: モンスター | F34: 男の子向け | G34: ノーマル | H34: ひこう | K34: =IF(テーブル2[[#This Row],[言われた回数]]>2,"多数派","少数派") -> 少数派 | Q34: =COUNTIFS(全コメントデータ!C:C,テーブル2[[#This Row],[ポケモン]],全コメントデータ!G:G,"<>"&"") -> 1
A35: ランクルス | B35: =COUNTIFS(全コメントデータ!C:C,テーブル2[[#This Row],[ポケモン]],全コメントデータ!D:D,"<>"&"自己レス") -> 2 | C35: =COUNTIFS(全コメントデータ!C:C,テーブル2[[#This Row],[ポケモン]],全コメントデータ!D:D,"自己レスの前") -> 2 | D35: =COUNTIFS(全コメントデータ!C:C,テーブル2[[#This Row],[ポケモン]],全コメントデータ!D:D,"自己レスの後") -> 0 | E35: テクニカル | F35: 男の子向け | G35: エスパー | H35: 0 | I35: ややマイナー | K35: =IF(テーブル2[[#This Row],[言われた回数]]>2,"多数派","少数派") -> 少数派 | L35: ある意味かわいい | M35: 普通 | N35: 普通 | P35: 普通 | Q35: =COUNTIFS(全コメントデータ!C:C,テーブル2[[#This Row],[ポケモン]],全コメントデータ!G:G,"<>"&"") -> 1
A36: リザードン | B36: =COUNTIFS(全コメントデータ!C:C,テーブル2[[#This Row],[ポケモン]],全コメントデータ!D:D,"<>"&"自己レス") -> 2 | C36: =COUNTIFS(全コメントデータ!C:C,テーブル2[[#This Row],[ポケモン]],全コメントデータ!D:D,"自己レスの前") -> 2 | D36: =COUNTIFS(全コメントデータ!C:C,テーブル2[[#This Row],[ポケモン]],全コメントデータ!D:D,"自己レスの後") -> 0 | E36: かっこいい | F36: 男の子向け | G36: ほのお | H36: ひこう | J36: レッド、ダンデ | K36: =IF(テーブル2[[#This Row],[言われた回数]]>2,"多数派","少数派") -> 少数派 | Q36: =COUNTIFS(全コメントデータ!C:C,テーブル2[[#This Row],[ポケモン]],全コメントデータ!G:G,"<>"&"") -> 1
A37: ハガネール | B37: =COUNTIFS(全コメントデータ!C:C,テーブル2[[#This Row],[ポケモン]],全コメントデータ!D:D,"<>"&"自己レス") -> 2 | C37: =COUNTIFS(全コメントデータ!C:C,テーブル2[[#This Row],[ポケモン]],全コメントデータ!D:D,"自己レスの前") -> 2 | D37: =COUNTIFS(全コメントデータ!C:C,テーブル2[[#This Row],[ポケモン]],全コメントデータ!D:D,"自己レスの後") -> 0 | E37: いかつい | F37: 男の子向け | G37: はがね | H37: じめん | J37: ポピー、ミカン | K37: =IF(テーブル2[[#This Row],[言われた回数]]>2,"多数派","少数派") -> 少数派 | Q37: =COUNTIFS(全コメントデータ!C:C,テーブル2[[#This Row],[ポケモン]],全コメントデータ!G:G,"<>"&"") -> 1
A38: ギャラドス | B38: =COUNTIFS(全コメントデータ!C:C,テーブル2[[#This Row],[ポケモン]],全コメントデータ!D:D,"<>"&"自己レス") -> 2 | C38: =COUNTIFS(全コメントデータ!C:C,テーブル2[[#This Row],[ポケモン]],全コメントデータ!D:D,"自己レスの前") -> 2 | D38: =COUNTIFS(全コメントデータ!C:C,テーブル2[[#This Row],[ポケモン]],全コメントデータ!D:D,"自己レスの後") -> 0 | E38: いかつい | F38: 男の子向け | G38: みず | H38: ひこう | J38: ワタル | K38: =IF(テーブル2[[#This Row],[言われた回数]]>2,"多数派","少数派") -> 少数派 | Q38: =COUNTIFS(全コメントデータ!C:C,テーブル2[[#This Row],[ポケモン]],全コメントデータ!G:G,"<>"&"") -> 1
A39: オーロンゲ | B39: =COUNTIFS(全コメントデータ!C:C,テーブル2[[#This Row],[ポケモン]],全コメントデータ!D:D,"<>"&"自己レス") -> 2 | C39: =COUNTIFS(全コメントデータ!C:C,テーブル2[[#This Row],[ポケモン]],全コメントデータ!D:D,"自己レスの前") -> 2 | D39: =COUNTIFS(全コメントデータ!C:C,テーブル2[[#This Row],[ポケモン]],全コメントデータ!D:D,"自己レスの後") -> 0 | E39: いかつい | F39: 男の子向け | G39: あく | H39: フェアリー | J39: マリィ | K39: =IF(テーブル2[[#This Row],[言われた回数]]>2,"多数派","少数派") -> 少数派 | Q39: =COUNTIFS(全コメントデータ!C:C,テーブル2[[#This Row],[ポケモン]],全コメントデータ!G:G,"<>"&"") -> 1
A40: チュリネ | B40: =COUNTIFS(全コメントデータ!C:C,テーブル2[[#This Row],[ポケモン]],全コメントデータ!D:D,"<>"&"自己レス") -> 2 | C40: =COUNTIFS(全コメントデータ!C:C,テーブル2[[#This Row],[ポケモン]],全コメントデータ!D:D,"自己レスの前") -> 2 | D40: =COUNTIFS(全コメントデータ!C:C,テーブル2[[#This Row],[ポケモン]],全コメントデータ!D:D,"自己レスの後") -> 0 | E40: かわいい | F40: 女の子向け | G40: くさ | H40: 0 | K40: =IF(テーブル2[[#This Row],[言われた回数]]>2,"多数派","少数派") -> 少数派 | Q40: =COUNTIFS(全コメントデータ!C:C,テーブル2[[#This Row],[ポケモン]],全コメントデータ!G:G,"<>"&"") -> 1
...

Sheet 印象集計
A18: 印象集計 | F18: 印象の多数派VS少数派 | L18: 印象の多数派VS少数派
A19: 行ラベル | B19: 合計 / 言われた回数 | F19: 合計 / 言われた回数 | G19: 列ラベル | L19: 合計 / 言われた回数 | M19: 列ラベル
A20: かわいい | B20: 166 | F20: 行ラベル | G20: 多数派 | H20: 総計 | L20: 行ラベル | M20: 少数派 | N20: 総計
A21: モンスター | B21: 46 | F21: かわいい | G21: 98 | H21: 98 | L21: かわいい | M21: 68 | N21: 68
A22: コミカル | B22: 42 | F22: モンスター | G22: 10 | H22: 10 | L22: モンスター | M22: 36 | N22: 36
A23: 強い | B23: 25 | F23: 強い | G23: 10 | H23: 10 | L23: コミカル | M23: 36 | N23: 36
A24: いかつい | B24: 21 | F24: スプーキー | G24: 7 | H24: 7 | L24: いかつい | M24: 21 | N24: 21
A25: かっこいい | B25: 19 | F25: かっこいい | G25: 7 | H25: 7 | L25: 強い | M25: 15 | N25: 15
A26: きもい | B26: 12 | F26: コミカル | G26: 6 | H26: 6 | L26: かっこいい | M26: 12 | N26: 12
A27: スプーキー | B27: 11 | F27: 総計 | G27: 138 | H27: 138 | L27: きもい | M27: 12 | N27: 12
A28: テクニカル | B28: 8 | L28: テクニカル | M28: 8 | N28: 8
A29: 総計 | B29: 350 | L29: スプーキー | M29: 4 | N29: 4
L30: 総計 | M30: 212 | N30: 212
B32: ジェンダー集計（票数）
B33: 合計 / 言われた回数 | C33: 列ラベル
B34: 行ラベル | C34: 少数派 | D34: 多数派 | E34: 総計
B35: ネタ枠 | C35: 2 | E35: 2
B36: 女の子向け | C36: 80 | D36: 101 | E36: 181
B37: 男の子向け | C37: 130 | D37: 37 | E37: 167
B38: 総計 | C38: 212 | D38: 138 | E38: 350
B40: ジェンダー集計（ポケモン種類数）
B41: 個数 / ポケモン | C41: 列ラベル
B42: 行ラベル | C42: 少数派 | D42: 多数派 | E42: 総計
B43: ネタ枠 | C43: 1 | E43: 1
B44: 女の子向け | C44: 67 | D44: 20 | E44: 87
B45: 男の子向け | C45: 107 | D45: 9 | E45: 116
B46: 総計 | C46: 175 | D46: 29 | E46: 204

Sheet タイプカウント
A1: ※場合によっては数式の中の行番号を更新する必要があります
A2: タイプ番号 | B2: タイプ | C2: １と２のあわせた出現回数
A3: 1 | B3: ノーマル | C3: {=SUMPRODUCT(((ポケモンマスタ!G$2:G$205=B3)+(ポケモンマスタ!H$2:H$205=B3))*(ポケモンマスタ!B$2:B$205))} -> 80
A4: 18 | B4: フェアリー | C4: {=SUMPRODUCT(((ポケモンマスタ!G$2:G$205=B4)+(ポケモンマスタ!H$2:H$205=B4))*(ポケモンマスタ!B$2:B$205))} -> 76
A5: 11 | B5: エスパー | C5: {=SUMPRODUCT(((ポケモンマスタ!G$2:G$205=B5)+(ポケモンマスタ!H$2:H$205=B5))*(ポケモンマスタ!B$2:B$205))} -> 43
A6: 14 | B6: ゴースト | C6: {=SUMPRODUCT(((ポケモンマスタ!G$2:G$205=B6)+(ポケモンマスタ!H$2:H$205=B6))*(ポケモンマスタ!B$2:B$205))} -> 38
A7: 3 | B7: みず | C7: {=SUMPRODUCT(((ポケモンマスタ!G$2:G$205=B7)+(ポケモンマスタ!H$2:H$205=B7))*(ポケモンマスタ!B$2:B$205))} -> 35
A8: 10 | B8: ひこう | C8: {=SUMPRODUCT(((ポケモンマスタ!G$2:G$205=B8)+(ポケモンマスタ!H$2:H$205=B8))*(ポケモンマスタ!B$2:B$205))} -> 31
A9: 5 | B9: くさ | C9: {=SUMPRODUCT(((ポケモンマスタ!G$2:G$205=B9)+(ポケモンマスタ!H$2:H$205=B9))*(ポケモンマスタ!B$2:B$205))} -> 30
A10: 8 | B10: どく | C10: {=SUMPRODUCT(((ポケモンマスタ!G$2:G$205=B10)+(ポケモンマスタ!H$2:H$205=B10))*(ポケモンマスタ!B$2:B$205))} -> 29
A11: 4 | B11: でんき | C11: {=SUMPRODUCT(((ポケモンマスタ!G$2:G$205=B11)+(ポケモンマスタ!H$2:H$205=B11))*(ポケモンマスタ!B$2:B$205))} -> 26
A12: 17 | B12: はがね | C12: {=SUMPRODUCT(((ポケモンマスタ!G$2:G$205=B12)+(ポケモンマスタ!H$2:H$205=B12))*(ポケモンマスタ!B$2:B$205))} -> 25
A13: 9 | B13: じめん | C13: {=SUMPRODUCT(((ポケモンマスタ!G$2:G$205=B13)+(ポケモンマスタ!H$2:H$205=B13))*(ポケモンマスタ!B$2:B$205))} -> 19
A14: 7 | B14: かくとう | C14: {=SUMPRODUCT(((ポケモンマスタ!G$2:G$205=B14)+(ポケモンマスタ!H$2:H$205=B14))*(ポケモンマスタ!B$2:B$205))} -> 15
... A20: 6 | B20: こおり | C20: {=SUMPRODUCT(((ポケモンマスタ!G$2:G$205=B20)+(ポケモンマスタ!H$2:H$205=B20))*(ポケモンマスタ!B$2:B$205))} -> 7

Sheet 複数あげた人の意見
A1: 行ラベル | B1: 合計 / 一人で複数あげている人があげた回数
A2: かわいい | B2: 84
A3: モンスター | B3: 19
A4: コミカル | B4: 17
A5: かっこいい | B5: 15
A6: いかつい | B6: 14
A7: 強い | B7: 11
A8: テクニカル | B8: 6
A9: スプーキー | B9: 6
A10: きもい | B10: 4
A11: 総計 | B11: 176
A13: タイプ番号 | B13: タイプ | C13: １と２のあわせた出現回数
A14: 1 | B14: ノーマル | C14: {=SUMPRODUCT(((ポケモンマスタ!G$2:G$205=B14)+(ポケモンマスタ!H$2:H$205=B14))*(ポケモンマスタ!Q$2:Q$205))} -> 38
A15: 18 | B15: フェアリー | C15: {=SUMPRODUCT(((ポケモンマスタ!G$2:G$205=B15)+(ポケモンマスタ!H$2:H$205=B15))*(ポケモンマスタ!Q$2:Q$205))} -> 37
A16: 14 | B16: ゴースト | C16: {=SUMPRODUCT(((ポケモンマスタ!G$2:G$205=B16)+(ポケモンマスタ!H$2:H$205=B16))*(ポケモンマスタ!Q$2:Q$205))} -> 22
A17: 10 | B17: ひこう | C17: {=SUMPRODUCT(((ポケモンマスタ!G$2:G$205=B17)+(ポケモンマスタ!H$2:H$205=B17))*(ポケモンマスタ!Q$2:Q$205))} -> 20
A18: 11 | B18: エスパー | C18: {=SUMPRODUCT(((ポケモンマスタ!G$2:G$205=B18)+(ポケモンマスタ!H$2:H$205=B18))*(ポケモンマスタ!Q$2:Q$205))} -> 18
A19: 3 | B19: みず | C19: {=SUMPRODUCT(((ポケモンマスタ!G$2:G$205=B19)+(ポケモンマスタ!H$2:H$205=B19))*(ポケモンマスタ!Q$2:Q$205))} -> 17
A20: 5 | B20: くさ | C20: {=SUMPRODUCT(((ポケモンマスタ!G$2:G$205=B20)+(ポケモンマスタ!H$2:H$205=B20))*(ポケモンマスタ!Q$2:Q$205))} -> 15
A21: 8 | B21: どく | C21: {=SUMPRODUCT(((ポケモンマスタ!G$2:G$205=B21)+(ポケモンマスタ!H$2:H$205=B21))*(ポケモンマスタ!Q$2:Q$205))} -> 15
A22: 17 | B22: はがね | C22: {=SUMPRODUCT(((ポケモンマスタ!G$2:G$205=B22)+(ポケモンマスタ!H$2:H$205=B22))*(ポケモンマスタ!Q$2:Q$205))} -> 12
A23: 4 | B23: でんき | C23: {=SUMPRODUCT(((ポケモンマスタ!G$2:G$205=B23)+(ポケモンマスタ!H$2:H$205=B23))*(ポケモンマスタ!Q$2:Q$205))} -> 10
A24: 7 | B24: かくとう | C24: {=SUMPRODUCT(((ポケモンマスタ!G$2:G$205=B24)+(ポケモンマスタ!H$2:H$205=B24))*(ポケモンマスタ!Q$2:Q$205))} -> 10
A25: 15 | B25: ドラゴン | C25: {=SUMPRODUCT(((ポケモンマスタ!G$2:G$205=B25)+(ポケモンマスタ!H$2:H$205=B25))*(ポケモンマスタ!Q$2:Q$205))} -> 10
... A31: 13 | B31: いわ | C31: {=SUMPRODUCT(((ポケモンマスタ!G$2:G$205=B31)+(ポケモンマスタ!H$2:H$205=B31))*(ポケモンマスタ!Q$2:Q$205))} -> 4

Sheet パーティづくり
A1: 249番までで、自己レス前を優先して検討。
A3: 得票数上位（総合） | B3: 得票数上位（自己レス前） | C3: 得票数上位（自己レス後）
A4: カイリュー | B4: カイリュー | C4: イーブイ
A5: イーブイ | B5: ミミッキュ | C5: ピクシー
A6: プクリン | B6: トゲピー
A7: ピクシー | B7: プリン
A8: ミミッキュ | B8: ゲンガー
A9: トゲピー
A10: プリン
A11: ゲンガー
A12: ピッピ
A13: ミミロップ
A15: ー | B15: 多いタイプの代表 | D15: ー | E15: 言及タイプの代表
A16: ノーマル | B16: イーブイ | D16: 可愛い系のノーマル | E16: プリン
A17: ノーマル | B17: ラッキー | D17: くさ | E17: ナゾノクサ
A18: フェアリー | B18: トゲピー | D18: はがね | E18: ハガネール
A19: フェアリー | B19: プリン | D19: くさ | E19: チュリネ
A20: どく | B20: ゲンガー | D20: ゴースト・エスパー・フェアリー | E20: ミミッキュ
A21: ひこう | B21: カイリュー | D21: 元ノーマルのフェアリー | E21: トゲピー
A22: エスパー | B22: サーナイト | D22: あく | E22: ブラッキー
A23: ゴースト | B23: ミミッキュ
B25: 多い印象の代表 | E25: 言及印象の代表
A26: かわいい | B26: プリン | D26: 厨パ | E26: ゲンガー
A27: かわいい | B27: トゲピー | D27: ゆびをふる | E27: ピッピ
A28: かわいい | B28: ミミッキュ | D28: メンヘラ | E28: ミミッキュ
A29: コミカル | B29: カビゴン | D29: 夢特性 | E29: カイリュー
A30: いかつい | B30: オーロンゲ | D30: 搦め手 | E30: グライオン
A31: きもい | B31: ルージュラ | D31: 耐久カイリュー | E31: カイリュー
D32: 自爆系 | E32: マルマイン
A34: まとめ
A35: カイリュー
A36: イーブイ
A37: プクリン
A38: ピクシー
A39: ミミッキュ
A40: トゲピー
A41: プリン
A42: ゲンガー
A43: ピッピ
A44: ミミロップ
...
